Workbook

Sheet Catálogo Completo
A1: Item # | B1: Scale | C1: Category | D1: Subcategory | E1: Product / Line | F1: Abbreviation | G1: Length (mm) | H1: Length (in) | I1: Radius (mm) | J1: Angle (°) | K1: Qty per Pack | L1: Color / Variant | M1: Price USD | N1: Functionality / Description | O1: PDF Page
A2: 106-0018 | B2: N | C2: Starter Set | D2: Passenger | E2: Santa Fe Super Chief N Scale Starter Set | K2: 1 set | M2: 330 | N2: Complete N-scale starter set: Santa Fe Super Chief locomotive + passenger consist + full oval of Unitrack + Power Pack SX. Layout 1337×677 mm. | O2: 5
A3: 106-0031 | B3: N | C3: Starter Set | D3: Passenger | E3: MP36PH + Bi-Level Chicago Metra | K3: 1 set | M3: 330 | N3: MP36PH commuter locomotive with Bi-Level Metra cars, full Unitrack oval + Power Pack SX. | O3: 5
A4: 106-0032 | B4: N | C4: Starter Set | D4: Passenger | E4: F40PH + Bi-Level Chicago Metra Starter Set | K4: 1 set | M4: 310 | N4: F40PH commuter loco + Bi-Level Metra cars, complete loop + Power Pack. | O4: 5
A5: 106-0037 | B5: N | C5: Starter Set | D5: Passenger | E5: F40PH Gallery Bi-Level Car Starter Set - New Metra Paint | K5: 1 set | M5: 350 | N5: F40PH + Bi-Level gallery cars in new Metra paint, complete loop + Power Pack. | O5: 5
A6: 106-0041 | B6: N | C6: Starter Set | D6: Passenger | E6: Silver Streak Zephyr Starter Set | K6: 1 set | M6: 350 | N6: Silver Streak Zephyr passenger set with Unitrack oval + Power Pack. | O6: 5
A7: 106-0047 | B7: N | C7: Starter Set | D7: Passenger | E7: ALC-42 Phase VII, Amtrak Viewliner II Starter Set | F7: ALC-42 | K7: 1 set | M7: 360 | N7: Amtrak ALC-42 loco + Viewliner II cars, full Unitrack oval + Power Pack. | O7: 5
A8: 106-0048 | B8: N | C8: Starter Set | D8: Passenger | E8: SC-44, Amtrak Pacific Surfliner Starter Set | F8: SC-44 | K8: 1 set | M8: 330 | N8: SC-44 Charger + Pacific Surfliner consist, full Unitrack oval + Power Pack. | O8: 5
A9: 106-0049 | B9: N | C9: Starter Set | D9: Freight | E9: F7A Freight Train Starter Set AT&SF | F9: F7A | K9: 1 set | L9: AT&SF | M9: 350 | N9: F7A loco with AT&SF Warbonnet freight consist, full loop + Power Pack. | O9: 5
A10: 106-0050 | B10: N | C10: Starter Set | D10: Freight | E10: F7A Freight Train Starter Set Union Pacific | F10: F7A | K10: 1 set | L10: UP | M10: 350 | N10: F7A loco with Union Pacific freight consist, full loop + Power Pack. | O10: 5
A11: 106-0051 | B11: N | C11: Starter Set | D11: Freight | E11: F7A Freight Train Starter Set AT&SF Bluebonnet | F11: F7A | K11: 1 set | L11: AT&SF Bluebonnet | M11: 350 | N11: F7A loco in AT&SF Bluebonnet scheme + freight cars, full loop + Power Pack. | O11: 5
A12: 106-0020 | B12: N | C12: Starter Set | D12: Freight | E12: ES44AC Mixed Freight Starter Set - Canadian National | F12: ES44AC | K12: 1 set | L12: CN | M12: 290 | N12: GE ES44AC + mixed freight cars (hoppers, gondolas, tank cars), full Unitrack oval + Power Pack. | O12: 5
A13: 106-0021 | B13: N | C13: Starter Set | D13: Freight | E13: ES40DC Mixed Freight Starter Set - CSX Boxcar | F13: ES40DC | K13: 1 set | L13: CSX | M13: 290 | N13: GE ES40DC + CSX mixed freight, full Unitrack oval + Power Pack. | O13: 5
A14: 106-0022 | B14: N | C14: Starter Set | D14: Freight | E14: ES44AC Mixed Freight Starter Set - Canadian Pacific | F14: ES44AC | K14: 1 set | L14: CP | M14: 290 | N14: GE ES44AC + CP mixed freight, full Unitrack oval + Power Pack. | O14: 5
A15: 106-0023 | B15: N | C15: Starter Set | D15: Freight | E15: ES44AC Mixed Freight Starter Set - Union Pacific | F15: ES44AC | K15: 1 set | L15: UP | M15: 290 | N15: GE ES44AC + UP mixed freight, full Unitrack oval + Power Pack. | O15: 5
A16: 106-0024 | B16: N | C16: Starter Set | D16: Freight | E16: ES44AC Mixed Freight Starter Set - BNSF Swoosh | F16: ES44AC | K16: 1 set | L16: BNSF Swoosh | M16: 290 | N16: GE ES44AC + BNSF Swoosh mixed freight, full Unitrack oval + Power Pack. | O16: 5
A17: 106-0026 | B17: N | C17: Starter Set | D17: Freight | E17: N GE ES44 Mixed Freight Starter Set - Florida East Coast | F17: ES44 | K17: 1 set | L17: FEC | M17: 290 | N17: GE ES44 + FEC mixed freight, full Unitrack oval + Power Pack. | O17: 5
A18: 106-0027 | B18: N | C18: Starter Set | D18: Freight | E18: ES44AC Mixed Freight Starter Set - CPKC | F18: ES44AC | K18: 1 set | L18: CPKC | M18: 290 | N18: GE ES44AC + CPKC mixed freight, full Unitrack oval + Power Pack. | O18: 5
A19: 20-852 | B19: N | C19: Master Set | D19: Track Set | E19: M1 Basic Oval Track Set | F19: M1 | K19: 1 set | M19: 120 | N19: Master oval-track set (no train): 4× S248, 1× S124, 1× Road Crossing 124, 1× S62, 1× Feeder S62, 8× R315-45° curves, Power Pack SX, AC adapter, cables, rerailer. Layout 1337×677 mm. | O19: 5
A20: 20-853 | B20: N | C20: Master Set | D20: Track Set | E20: M2 Basic Oval Track and Passing Track Set | F20: M2 | K20: 1 set | M20: 220 | N20: M1 contents + V1 passing siding set: adds 6× S248, 2× S64, 2× R718-15°, 1× EP718-15L #6 left turnout, 1× EP718-15R right turnout, 2× turnout switches. Layout 2019×751 mm. | O20: 5
A21: 20-860 | B21: N | C21: V-Series Set | D21: Expansion | E21: V1 Mainline Passing Siding Set | F21: V1 | K21: 1 set | M21: 100 | N21: Add a station and enjoy trains passing/switching: 6× S248, 2× S64, 2× R718-15°, 1× EP718-15L, 1× EP718-15R, 2× turnout switches. 1364×91 mm. | O21: 6
A22: 20-861 | B22: N | C22: V-Series Set | D22: Expansion | E22: V2 Single Track Viaduct Set | F22: V2 | K22: 1 set | M22: 120 | N22: Bridge for overhead crossing: 4× S248, 4× S248V, 2× S124V, 8× R315-45V, 1× S248T (truss bridge), Incline Pier Set, 4× Pier #5. 1655×911 mm. | O22: 6
A23: 20-862 | B23: N | C23: V-Series Set | D23: Expansion | E23: V3 Rail Yard Switching Track Set | F23: V3 | K23: 1 set | M23: 145 | N23: Sidetrack rail yard set: 6× S248, 2× S186, 2× S64, 3× S62B-A (bumper A), 3× R718-15°, 2× EP718-15L, 1× EP718-15R, 3× turnout switches. 1571×250 mm. | O23: 6
A24: 20-863 | B24: N | C24: V-Series Set | D24: Expansion | E24: V4 Switching Siding Set | F24: V4 | K24: 1 set | M24: 120 | N24: Station / signal-tower where trains pass: 4× S248, 2× S62, 2× R481-15°, 1× EP481-15L, 1× EP481-15R, 2× S60L, 2× S60R, 2× turnout switches. 992×58 mm. | O24: 6
A25: 20-864 | B25: N | C25: V-Series Set | D25: Expansion | E25: V5 Inner Oval Track Set for Starter/M1 Set | F25: V5 | K25: 1 set | M25: 60 | N25: Inner oval for Starter or M1 (no Power Pack): 4× S248, 1× S124, 1× S124C, 1× S62, 1× S62F (feeder), 8× R282-45°, rerailer, feeder cable. 1271×611 mm. | O25: 6
A26: 20-865 | B26: N | C26: V-Series Set | D26: Expansion | E26: V6 Outer Oval Track Set for Starter/M1 Set | F26: V6 | K26: 1 set | M26: 60 | N26: Outer oval for Starter or M1 (no Power Pack): 4× S248, 1× S124, 1× S124C, 1× S62, 1× S62F, 8× R348-45°, rerailer, feeder cable. 1403×743 mm. | O26: 6
A27: 20-866 | B27: N | C27: V-Series Set | D27: Expansion | E27: V7 Double Crossover Track Set | F27: V7 | K27: 1 set | M27: 90 | N27: Turnouts + diamond crossover to change trains between two tracks either direction: 1× W×310, 2× S248, 2× S62, 1× turnout switch. 310×58 mm. | O27: 6
A28: 20-870 | B28: N | C28: V-Series Set | D28: Double Track | E28: V11 Double Track Set R414/381 | F28: V11 | K28: 1 set | M28: 185 | N28: Two trains through banked, superelevated curves: 7× WS248PC, 1× WS124PC, 1× WS62PC, 1× WS62FPC, 8× WR414/381-45PC, 4× WR414/381-22.5PCAL, 4× WR414/381-22.5PCAR. 2335×1261 mm. | O28: 6
A29: 20-871 | B29: N | C29: V-Series Set | D29: Double Track Viaduct | E29: V12 Double Track Viaduct Set R414/381 | F29: V12 | K29: 1 set | M29: 225 | N29: Take double track ground→viaduct via piers + superelevated curves; includes double-track truss bridge. WS186PC×2, WS124PC×2, WS62PC×1, WS248VPC×6, WS186VPC×1, WS124VPC×2, WS248T×1, WR414/381-22.5VPC×4, WR414/381-22.5VPCAL×2, WR414/381-22.5VPCAR×2, WS186PCINC×2, Double Track Pier Set, Piers for Double Track Viaducts×3, Piers for Truss Bridge×2. | O29: 7
A30: 20-872 | B30: N | C30: V-Series Set | D30: Double Track Viaduct | E30: V13 Double Track Elevated Loop Set R414/381 | F30: V13 | K30: 1 set | M30: 240 | N30: Run trains around an elevated loop: 8× WS248VS, 6× WR414/381-45VS, 6× WR414/381-22.5VSAL, 2× WR414/381-22.5VSAR, 18× Double Track Pier, 2× Double Track Viaduct Power Cord. 1864×872 mm. | O30: 7
... A34: 20-877 | B34: N | C34: V-Series Set | D34: Slab Track | E34: V17 Concrete Slab Double Track Oval Set R414/381 | F34: V17 | K34: 1 set | M34: 90 | N34: Concrete-slab loop for urban subway scenes: 4× WS248S, 1× WS124S, 1× WS62S, 1× WS62FS, 6× WR414/381-45S, 2× WR414/381SAL, 2× WR414/381SAR. 1473×753 mm. | O34: 7
A35: 20-000 | B35: N | C35: Straight Track | D35: Single | E35: N Straight Track 248mm | F35: S248 | G35: 248 | H35: 9 3/4" | K35: 4 pcs | M35: 12 | N35: Standard 248 mm straight track — the base length of the Unitrack straight system. Black wooden ties. | O35: 10
A36: 20-007 | B36: N | C36: Straight Track | D36: Concrete-Tie | E36: N Concrete Tie Straight Track 248mm | F36: S248PC | G36: 248 | H36: 9 3/4" | K36: 4 pcs | M36: 12.5 | N36: 248 mm straight with modern concrete ties for high-speed/modern scenes. | O36: 10
A37: 20-010 | B37: N | C37: Straight Track | D37: Single | E37: N Straight Track 186mm | F37: S186 | G37: 186 | H37: 7 5/16" | K37: 4 pcs | M37: 10 | N37: 186 mm straight track = 3/4 of S248 length. | O37: 10
A38: 20-020 | B38: N | C38: Straight Track | D38: Single | E38: N Straight Track 124mm | F38: S124 | G38: 124 | H38: 4 7/8" | K38: 4 pcs | M38: 9.5 | N38: 124 mm straight track = 1/2 of S248 length. | O38: 10
A39: 20-028 | B39: N | C39: Straight Track | D39: Concrete-Tie | E39: N Concrete Tie Straight Track 124mm | F39: S124PC | G39: 124 | H39: 4 7/8" | K39: 4 pcs | M39: 11 | N39: 124 mm straight with concrete ties. | O39: 10
A40: 20-026 | B40: N | C40: Straight Track | D40: Re-Railer | E40: N Re-Railer Track 124mm | F40: S124RE | G40: 124 | H40: 4 7/8" | K40: 2 pcs | M40: 7 | N40: Re-railer disguised as road crossing — slides derailed cars back onto rails. | O40: 10
A41: 20-027-1 | B41: N | C41: Straight Track | D41: Crossing/Re-Railer | E41: N Crossing Gate & Re-Railer Track 124mm | G41: 124 | H41: 4 7/8" | K41: 1 pc | M41: 18 | N41: Functional grade-crossing gate combined with re-railer. | O41: 10
A42: 20-400 | B42: N | C42: Viaduct Straight | D42: Viaduct | E42: N Single Track Viaduct Straight Track 248mm | F42: S248V | G42: 248 | H42: 9 3/4" | K42: 2 pcs | M42: 13.5 | N42: Elevated straight viaduct track 248 mm; uses S-Joiner with pier products. | O42: 10
A43: 20-410 | B43: N | C43: Viaduct Straight | D43: Viaduct | E43: N Single Track Viaduct Straight Track 186mm | F43: S186V | G43: 186 | H43: 7 5/16" | K43: 2 pcs | M43: 13 | N43: Elevated straight viaduct track 186 mm. | O43: 10
...

Sheet Resumen
A1: KATO UNITRACK — Resumen del Catálogo
A3: Fuente | B3: us_unitrack_1-40_20251028 (KATO HO & N Track Catalog, 2023 MSRP)
A4: Total ítems | B4: =COUNTA('Catálogo Completo'!A2:A331) -> 330
A5: Ítems N scale | B5: =COUNTIF('Catálogo Completo'!B2:B331,"N") -> 224
A6: Ítems HO scale | B6: =COUNTIF('Catálogo Completo'!B2:B331,"HO") -> 61
A7: Ítems accesorios | B7: =COUNTIF('Catálogo Completo'!B2:B331,"Acc") -> 45
A8: Precio mínimo (USD) | B8: =MIN('Catálogo Completo'!M2:M331) -> 2
A9: Precio máximo (USD) | B9: =MAX('Catálogo Completo'!M2:M331) -> 420
A10: Precio promedio (USD) | B10: =AVERAGE('Catálogo Completo'!M2:M331) -> 51.778875
A11: Valor total catálogo (USD) | B11: =SUM('Catálogo Completo'!M2:M331) -> 17035.25
A14: Categoría | B14: Cantidad | C14: Subtotal USD
A15: Adjustment Track | B15: =COUNTIF('Catálogo Completo'!C2:C331,A15) -> 5 | C15: =SUMIF('Catálogo Completo'!C2:C331,A15,'Catálogo Completo'!M2:M331) -> 114.25
A16: Bridge | B16: =COUNTIF('Catálogo Completo'!C2:C331,A16) -> 29 | C16: =SUMIF('Catálogo Completo'!C2:C331,A16,'Catálogo Completo'!M2:M331) -> 484.5
A17: Bridge Set | B17: =COUNTIF('Catálogo Completo'!C2:C331,A17) -> 2 | C17: =SUMIF('Catálogo Completo'!C2:C331,A17,'Catálogo Completo'!M2:M331) -> 165
A18: Building | B18: =COUNTIF('Catálogo Completo'!C2:C331,A18) -> 1 | C18: =SUMIF('Catálogo Completo'!C2:C331,A18,'Catálogo Completo'!M2:M331) -> 59
A19: Bumper Track | B19: =COUNTIF('Catálogo Completo'!C2:C331,A19) -> 7 | C19: =SUMIF('Catálogo Completo'!C2:C331,A19,'Catálogo Completo'!M2:M331) -> 74.25
A20: Cable | B20: =COUNTIF('Catálogo Completo'!C2:C331,A20) -> 9 | C20: =SUMIF('Catálogo Completo'!C2:C331,A20,'Catálogo Completo'!M2:M331) -> 55.5
A21: Catenary Pole | B21: =COUNTIF('Catálogo Completo'!C2:C331,A21) -> 12 | C21: =SUMIF('Catálogo Completo'!C2:C331,A21,'Catálogo Completo'!M2:M331) -> 216.5
A22: Compact Set | B22: =COUNTIF('Catálogo Completo'!C2:C331,A22) -> 3 | C22: =SUMIF('Catálogo Completo'!C2:C331,A22,'Catálogo Completo'!M2:M331) -> 197
A23: Controller | B23: =COUNTIF('Catálogo Completo'!C2:C331,A23) -> 1 | C23: =SUMIF('Catálogo Completo'!C2:C331,A23,'Catálogo Completo'!M2:M331) -> 170
A24: Crossing | B24: =COUNTIF('Catálogo Completo'!C2:C331,A24) -> 7 | C24: =SUMIF('Catálogo Completo'!C2:C331,A24,'Catálogo Completo'!M2:M331) -> 382.5
A25: Crossover | B25: =COUNTIF('Catálogo Completo'!C2:C331,A25) -> 1 | C25: =SUMIF('Catálogo Completo'!C2:C331,A25,'Catálogo Completo'!M2:M331) -> 75
A26: Curved Track | B26: =COUNTIF('Catálogo Completo'!C2:C331,A26) -> 37 | C26: =SUMIF('Catálogo Completo'!C2:C331,A26,'Catálogo Completo'!M2:M331) -> 554
A27: Double Track | B27: =COUNTIF('Catálogo Completo'!C2:C331,A27) -> 14 | C27: =SUMIF('Catálogo Completo'!C2:C331,A27,'Catálogo Completo'!M2:M331) -> 205
A28: Feeder Track | B28: =COUNTIF('Catálogo Completo'!C2:C331,A28) -> 4 | C28: =SUMIF('Catálogo Completo'!C2:C331,A28,'Catálogo Completo'!M2:M331) -> 39.5
A29: Flexible Track | B29: =COUNTIF('Catálogo Completo'!C2:C331,A29) -> 3 | C29: =SUMIF('Catálogo Completo'!C2:C331,A29,'Catálogo Completo'!M2:M331) -> 26
A30: Hardware | B30: =COUNTIF('Catálogo Completo'!C2:C331,A30) -> 1 | C30: =SUMIF('Catálogo Completo'!C2:C331,A30,'Catálogo Completo'!M2:M331) -> 3.5
A31: Joiner | B31: =COUNTIF('Catálogo Completo'!C2:C331,A31) -> 11 | C31: =SUMIF('Catálogo Completo'!C2:C331,A31,'Catálogo Completo'!M2:M331) -> 61
A32: Master Set | B32: =COUNTIF('Catálogo Completo'!C2:C331,A32) -> 4 | C32: =SUMIF('Catálogo Completo'!C2:C331,A32,'Catálogo Completo'!M2:M331) -> 880
A33: Pier | B33: =COUNTIF('Catálogo Completo'!C2:C331,A33) -> 10 | C33: =SUMIF('Catálogo Completo'!C2:C331,A33,'Catálogo Completo'!M2:M331) -> 189
A34: Power | B34: =COUNTIF('Catálogo Completo'!C2:C331,A34) -> 4 | C34: =SUMIF('Catálogo Completo'!C2:C331,A34,'Catálogo Completo'!M2:M331) -> 41.75
A35: Power Pack | B35: =COUNTIF('Catálogo Completo'!C2:C331,A35) -> 1 | C35: =SUMIF('Catálogo Completo'!C2:C331,A35,'Catálogo Completo'!M2:M331) -> 80
A36: Power Supply | B36: =COUNTIF('Catálogo Completo'!C2:C331,A36) -> 3 | C36: =SUMIF('Catálogo Completo'!C2:C331,A36,'Catálogo Completo'!M2:M331) -> 93
A37: Rerailer | B37: =COUNTIF('Catálogo Completo'!C2:C331,A37) -> 1 | C37: =SUMIF('Catálogo Completo'!C2:C331,A37,'Catálogo Completo'!M2:M331) -> 5
A38: Roadbed | B38: =COUNTIF('Catálogo Completo'!C2:C331,A38) -> 2 | C38: =SUMIF('Catálogo Completo'!C2:C331,A38,'Catálogo Completo'!M2:M331) -> 26
A39: Signal | B39: =COUNTIF('Catálogo Completo'!C2:C331,A39) -> 2 | C39: =SUMIF('Catálogo Completo'!C2:C331,A39,'Catálogo Completo'!M2:M331) -> 140
A40: Signal Switch | B40: =COUNTIF('Catálogo Completo'!C2:C331,A40) -> 1 | C40: =SUMIF('Catálogo Completo'!C2:C331,A40,'Catálogo Completo'!M2:M331) -> 17
A41: Slab Track | B41: =COUNTIF('Catálogo Completo'!C2:C331,A41) -> 7 | C41: =SUMIF('Catálogo Completo'!C2:C331,A41,'Catálogo Completo'!M2:M331) -> 95.5
A42: Sound Box | B42: =COUNTIF('Catálogo Completo'!C2:C331,A42) -> 1 | C42: =SUMIF('Catálogo Completo'!C2:C331,A42,'Catálogo Completo'!M2:M331) -> 315
A43: Sound Card | B43: =COUNTIF('Catálogo Completo'!C2:C331,A43) -> 11 | C43: =SUMIF('Catálogo Completo'!C2:C331,A43,'Catálogo Completo'!M2:M331) -> 377
...

Sheet Glosario Abreviaturas
A1: Abreviatura | B1: Significado
A2: S### | B2: Straight Track + length in mm (e.g., S248 = 248 mm straight)
A3: R### | B3: Curved Track + radius in mm (e.g., R315 = 315 mm radius curve)
A4: R###-## | B4: Curve radius + angle (e.g., R315-45 = R315 mm × 45° curve)
A5: EP### | B5: Electric Turnout with radius (e.g., EP481 = electric turnout R481)
A6: HP### | B6: Manual Turnout with radius (e.g., HP867L = HO manual #6 left R867)
A7: X-L / X-R | B7: Crossing track with left/right angle
A8: W prefix (e.g., WS248) | B8: Double-track version of an item
A9: WS###PC | B9: Double-track concrete-tie straight
A10: WS###S | B10: Double-track slab roadbed straight
A11: WS###VS / WS###VPC | B11: Double-track viaduct straight
A12: WR###/### | B12: Double-track curve — outer/inner radius (e.g., WR414/381)
... A38: DCC | B38: Digital Command Control — multiple-train control on same track
